Workbook

Sheet Volúmenes DIstribuidos 
A1: Nro. | B1: Fecha de despacho | C1: Producto / Alimento | D1: Peso unitario (kg) | E1: Peso bruto total (kg) | F1: Nº Beneficiarios | G1: Nº Niños | H1: N°Adultos
A3: 1 | B3: 44047 | C3: Aceite o grasas | D3: 23 | E3: =SUM(D3:D8) -> 138 | F3: =INT(MAX(D3:D8)) -> 23 | G3: =INT((F3/10)*2) -> 4 | H3: =F3-G3 -> 19
C4: Panadería | D4: 23
C5: Vegetales y hojas | D5: 23
C6: Fideo | D6: 23
C7: Carnes rojas | D7: 23
C8: Azúcar o dulce | D8: 23
A9: 2 | B9: 44050 | C9: Menestras | D9: 11.59 | E9: =SUM(D9:D14) -> 103.351 | F9: =INT(MAX(D9:D14)) -> 25 | G9: =INT((F9/10)*2) -> 5 | H9: =F9-G9 -> 20
C10: Vegetales y hojas | D10: 25.83
C11: Otros almidones | D11: 8.371
C12: Carnes blancas | D12: 20.34
C13: Azúcar o dulce | D13: 22.34
C14: Fideo | D14: 14.88
A15: 3 | B15: 44054 | C15: Lácteos | D15: 4.23 | E15: =SUM(D15:D20) -> 61.616 | F15: =INT(MAX(D15:D20)) -> 33 | G15: =INT((F15/10)*2) -> 6 | H15: =F15-G15 -> 27
C16: Vegetales y hojas | D16: 5.306
C17: Carnes blancas | D17: 7.09
C18: Aceite o grasas | D18: 6.87
C19: Menestras | D19: 33.06
C20: Azúcar o dulce | D20: 5.06
A21: 4 | B21: 44057 | C21: Carnes rojas | D21: 66.276 | E21: =SUM(D21:D26) -> 458.686 | F21: =INT(MAX(D21:D26)) -> 119 | G21: =INT((F21/10)*2) -> 23 | H21: =F21-G21 -> 96
C22: Menestras | D22: 34.63
C23: Aceite o grasas | D23: 77.75
C24: Panadería | D24: 103.38
C25: Otros almidones | D25: 119.26
C26: Azúcar o dulce | D26: 57.39
A27: 5 | B27: 44061 | C27: Otros almidones | D27: 49.58 | E27: =SUM(D27:D32) -> 339.181 | F27: =INT(MAX(D27:D32)) -> 134 | G27: =INT((F27/10)*2) -> 26 | H27: =F27-G27 -> 108
C28: Carnes blancas | D28: 72.34
C29: Panadería | D29: 35.47
C30: Aceite o grasas | D30: 12.21
C31: Vegetales y hojas | D31: 134.52
C32: Fideo | D32: 35.061
A33: 6 | B33: 44064 | C33: Salsas | D33: 60 | E33: =SUM(D33:D38) -> 352.493 | F33: =INT(MAX(D33:D38)) -> 80 | G33: =INT((F33/10)*2) -> 16 | H33: =F33-G33 -> 64
C34: Lácteos | D34: 55.62
C35: Carnes blancas | D35: 58.76
C36: Menestras | D36: 21.823
C37: Aceite o grasas | D37: 80.18
C38: Panadería | D38: 76.11
A39: 7 | B39: 44068 | C39: Azúcar o dulce | D39: 11.72 | E39: =SUM(D39:D44) -> 85.272 | F39: =INT(MAX(D39:D44)) -> 38 | G39: =INT((F39/10)*2) -> 7 | H39: =F39-G39 -> 31
C40: Otros almidones | D40: 11.88
C41: Menestras | D41: 4.49
...

Sheet Inventario
A1: Fecha | B1: Categoría de Alimento | C1: Tipo Movimiento | D1: Cantidad (kg) | E1: Stock Disponible (kg)
A2: 43980 | B2: Azúcar o dulce | C2: ENTRADA | D2: 69.52 | E2: =SUMIF('Parametros Inventario'!$A:$A,B2,'Parametros Inventario'!$B:$B)+SUMIFS(D$2:D2,B$2:B2,B2,C$2:C2,"ENTRADA")-SUMIFS(D$2:D2,B$2:B2,B2,C$2:C2,"SALIDA") -> 2026.52
A3: 43980 | B3: Otros almidones | C3: ENTRADA | D3: 219.21 | E3: =SUMIF('Parametros Inventario'!$A:$A,B3,'Parametros Inventario'!$B:$B)+SUMIFS(D$2:D3,B$2:B3,B3,C$2:C3,"ENTRADA")-SUMIFS(D$2:D3,B$2:B3,B3,C$2:C3,"SALIDA") -> 1590.21
A4: 43980 | B4: Fideo | C4: ENTRADA | D4: 150.69 | E4: =SUMIF('Parametros Inventario'!$A:$A,B4,'Parametros Inventario'!$B:$B)+SUMIFS(D$2:D4,B$2:B4,B4,C$2:C4,"ENTRADA")-SUMIFS(D$2:D4,B$2:B4,B4,C$2:C4,"SALIDA") -> 1493.69
A5: 43980 | B5: Panadería | C5: ENTRADA | D5: 189.74 | E5: =SUMIF('Parametros Inventario'!$A:$A,B5,'Parametros Inventario'!$B:$B)+SUMIFS(D$2:D5,B$2:B5,B5,C$2:C5,"ENTRADA")-SUMIFS(D$2:D5,B$2:B5,B5,C$2:C5,"SALIDA") -> 856.74
A6: 43980 | B6: Menestras | C6: ENTRADA | D6: 244.71 | E6: =SUMIF('Parametros Inventario'!$A:$A,B6,'Parametros Inventario'!$B:$B)+SUMIFS(D$2:D6,B$2:B6,B6,C$2:C6,"ENTRADA")-SUMIFS(D$2:D6,B$2:B6,B6,C$2:C6,"SALIDA") -> 932.71
A7: 43980 | B7: Carnes rojas | C7: ENTRADA | D7: 268 | E7: =SUMIF('Parametros Inventario'!$A:$A,B7,'Parametros Inventario'!$B:$B)+SUMIFS(D$2:D7,B$2:B7,B7,C$2:C7,"ENTRADA")-SUMIFS(D$2:D7,B$2:B7,B7,C$2:C7,"SALIDA") -> 895
A8: 43980 | B8: Carnes blancas | C8: ENTRADA | D8: 196.08 | E8: =SUMIF('Parametros Inventario'!$A:$A,B8,'Parametros Inventario'!$B:$B)+SUMIFS(D$2:D8,B$2:B8,B8,C$2:C8,"ENTRADA")-SUMIFS(D$2:D8,B$2:B8,B8,C$2:C8,"SALIDA") -> 1566.08
A9: 43980 | B9: Lácteos | C9: ENTRADA | D9: 209.12 | E9: =SUMIF('Parametros Inventario'!$A:$A,B9,'Parametros Inventario'!$B:$B)+SUMIFS(D$2:D9,B$2:B9,B9,C$2:C9,"ENTRADA")-SUMIFS(D$2:D9,B$2:B9,B9,C$2:C9,"SALIDA") -> 975.12
A10: 43980 | B10: Salsas | C10: ENTRADA | D10: 299.13 | E10: =SUMIF('Parametros Inventario'!$A:$A,B10,'Parametros Inventario'!$B:$B)+SUMIFS(D$2:D10,B$2:B10,B10,C$2:C10,"ENTRADA")-SUMIFS(D$2:D10,B$2:B10,B10,C$2:C10,"SALIDA") -> 1774.13
A11: 43980 | B11: Vegetales y hojas | C11: ENTRADA | D11: 222.25 | E11: =SUMIF('Parametros Inventario'!$A:$A,B11,'Parametros Inventario'!$B:$B)+SUMIFS(D$2:D11,B$2:B11,B11,C$2:C11,"ENTRADA")-SUMIFS(D$2:D11,B$2:B11,B11,C$2:C11,"SALIDA") -> 1161.25
A12: 43980 | B12: Aceite o grasas | C12: ENTRADA | D12: 286.96 | E12: =SUMIF('Parametros Inventario'!$A:$A,B12,'Parametros Inventario'!$B:$B)+SUMIFS(D$2:D12,B$2:B12,B12,C$2:C12,"ENTRADA")-SUMIFS(D$2:D12,B$2:B12,B12,C$2:C12,"SALIDA") -> 1699.96
A13: 43987 | B13: Azúcar o dulce | C13: ENTRADA | D13: 232.93 | E13: =SUMIF('Parametros Inventario'!$A:$A,B13,'Parametros Inventario'!$B:$B)+SUMIFS(D$2:D13,B$2:B13,B13,C$2:C13,"ENTRADA")-SUMIFS(D$2:D13,B$2:B13,B13,C$2:C13,"SALIDA") -> 2259.45
... A45: 44033 | B45: Aceite o grasas | C45: ENTRADA | D45: 95.77 | E45: =SUMIF('Parametros Inventario'!$A:$A,B45,'Parametros Inventario'!$B:$B)+SUMIFS(D$2:D45,B$2:B45,B45,C$2:C45,"ENTRADA")-SUMIFS(D$2:D45,B$2:B45,B45,C$2:C45,"SALIDA") -> 2039.03
A46: ='Volúmenes DIstribuidos '!B3 -> 44047 | B46: =IF(OR('Volúmenes DIstribuidos '!C3="Azúcar",'Volúmenes DIstribuidos '!C3="azúcar"),"Azúcar o dulce",IF('Volúmenes DIstribuidos '!C3="Aceite","Aceite o grasas",IF('Volúmenes DIstribuidos '!C3="Avena","Otros almidones",'Volúmenes DIstribuidos '!C3))) -> Aceite o grasas | C46: SALIDA | D46: ='Volúmenes DIstribuidos '!D3 -> 23 | E46: =SUMIF('Parametros Inventario'!$A:$A,B46,'Parametros Inventario'!$B:$B)+SUMIFS(D$2:D46,B$2:B46,B46,C$2:C46,"ENTRADA")-SUMIFS(D$2:D46,B$2:B46,B46,C$2:C46,"SALIDA") -> 2016.03
A47: ='Volúmenes DIstribuidos '!B3 -> 44047 | B47: =IF(OR('Volúmenes DIstribuidos '!C4="Azúcar",'Volúmenes DIstribuidos '!C4="azúcar"),"Azúcar o dulce",IF('Volúmenes DIstribuidos '!C4="Aceite","Aceite o grasas",IF('Volúmenes DIstribuidos '!C4="Avena","Otros almidones",'Volúmenes DIstribuidos '!C4))) -> Panadería | C47: SALIDA | D47: ='Volúmenes DIstribuidos '!D4 -> 23 | E47: =SUMIF('Parametros Inventario'!$A:$A,B47,'Parametros Inventario'!$B:$B)+SUMIFS(D$2:D47,B$2:B47,B47,C$2:C47,"ENTRADA")-SUMIFS(D$2:D47,B$2:B47,B47,C$2:C47,"SALIDA") -> 1347.6
A48: ='Volúmenes DIstribuidos '!B3 -> 44047 | B48: =IF(OR('Volúmenes DIstribuidos '!C5="Azúcar",'Volúmenes DIstribuidos '!C5="azúcar"),"Azúcar o dulce",IF('Volúmenes DIstribuidos '!C5="Aceite","Aceite o grasas",IF('Volúmenes DIstribuidos '!C5="Avena","Otros almidones",'Volúmenes DIstribuidos '!C5))) -> Vegetales y hojas | C48: SALIDA | D48: ='Volúmenes DIstribuidos '!D5 -> 23 | E48: =SUMIF('Parametros Inventario'!$A:$A,B48,'Parametros Inventario'!$B:$B)+SUMIFS(D$2:D48,B$2:B48,B48,C$2:C48,"ENTRADA")-SUMIFS(D$2:D48,B$2:B48,B48,C$2:C48,"SALIDA") -> 1663.43
A49: ='Volúmenes DIstribuidos '!B3 -> 44047 | B49: =IF(OR('Volúmenes DIstribuidos '!C6="Azúcar",'Volúmenes DIstribuidos '!C6="azúcar"),"Azúcar o dulce",IF('Volúmenes DIstribuidos '!C6="Aceite","Aceite o grasas",IF('Volúmenes DIstribuidos '!C6="Avena","Otros almidones",'Volúmenes DIstribuidos '!C6))) -> Fideo | C49: SALIDA | D49: ='Volúmenes DIstribuidos '!D6 -> 23 | E49: =SUMIF('Parametros Inventario'!$A:$A,B49,'Parametros Inventario'!$B:$B)+SUMIFS(D$2:D49,B$2:B49,B49,C$2:C49,"ENTRADA")-SUMIFS(D$2:D49,B$2:B49,B49,C$2:C49,"SALIDA") -> 1874.66
A50: ='Volúmenes DIstribuidos '!B3 -> 44047 | B50: =IF(OR('Volúmenes DIstribuidos '!C7="Azúcar",'Volúmenes DIstribuidos '!C7="azúcar"),"Azúcar o dulce",IF('Volúmenes DIstribuidos '!C7="Aceite","Aceite o grasas",IF('Volúmenes DIstribuidos '!C7="Avena","Otros almidones",'Volúmenes DIstribuidos '!C7))) -> Carnes rojas | C50: SALIDA | D50: ='Volúmenes DIstribuidos '!D7 -> 23 | E50: =SUMIF('Parametros Inventario'!$A:$A,B50,'Parametros Inventario'!$B:$B)+SUMIFS(D$2:D50,B$2:B50,B50,C$2:C50,"ENTRADA")-SUMIFS(D$2:D50,B$2:B50,B50,C$2:C50,"SALIDA") -> 1545.46
A51: ='Volúmenes DIstribuidos '!B3 -> 44047 | B51: =IF(OR('Volúmenes DIstribuidos '!C8="Azúcar",'Volúmenes DIstribuidos '!C8="azúcar"),"Azúcar o dulce",IF('Volúmenes DIstribuidos '!C8="Aceite","Aceite o grasas",IF('Volúmenes DIstribuidos '!C8="Avena","Otros almidones",'Volúmenes DIstribuidos '!C8))) -> Azúcar o dulce | C51: SALIDA | D51: ='Volúmenes DIstribuidos '!D8 -> 23 | E51: =SUMIF('Parametros Inventario'!$A:$A,B51,'Parametros Inventario'!$B:$B)+SUMIFS(D$2:D51,B$2:B51,B51,C$2:C51,"ENTRADA")-SUMIFS(D$2:D51,B$2:B51,B51,C$2:C51,"SALIDA") -> 2420.83
A52: 44050 | B52: Azúcar o dulce | C52: ENTRADA | D52: 234.92 | E52: =SUMIF('Parametros Inventario'!$A:$A,B52,'Parametros Inventario'!$B:$B)+SUMIFS(D$2:D52,B$2:B52,B52,C$2:C52,"ENTRADA")-SUMIFS(D$2:D52,B$2:B52,B52,C$2:C52,"SALIDA") -> 2655.75
A53: 44050 | B53: Otros almidones | C53: ENTRADA | D53: 50.52 | E53: =SUMIF('Parametros Inventario'!$A:$A,B53,'Parametros Inventario'!$B:$B)+SUMIFS(D$2:D53,B$2:B53,B53,C$2:C53,"ENTRADA")-SUMIFS(D$2:D53,B$2:B53,B53,C$2:C53,"SALIDA") -> 2027.78
A54: 44050 | B54: Fideo | C54: ENTRADA | D54: 186.88 | E54: =SUMIF('Parametros Inventario'!$A:$A,B54,'Parametros Inventario'!$B:$B)+SUMIFS(D$2:D54,B$2:B54,B54,C$2:C54,"ENTRADA")-SUMIFS(D$2:D54,B$2:B54,B54,C$2:C54,"SALIDA") -> 2061.54
A55: 44050 | B55: Panadería | C55: ENTRADA | D55: 66.89 | E55: =SUMIF('Parametros Inventario'!$A:$A,B55,'Parametros Inventario'!$B:$B)+SUMIFS(D$2:D55,B$2:B55,B55,C$2:C55,"ENTRADA")-SUMIFS(D$2:D55,B$2:B55,B55,C$2:C55,"SALIDA") -> 1414.49
A56: 44050 | B56: Menestras | C56: ENTRADA | D56: 61.17 | E56: =SUMIF('Parametros Inventario'!$A:$A,B56,'Parametros Inventario'!$B:$B)+SUMIFS(D$2:D56,B$2:B56,B56,C$2:C56,"ENTRADA")-SUMIFS(D$2:D56,B$2:B56,B56,C$2:C56,"SALIDA") -> 1330.48
A57: 44050 | B57: Carnes rojas | C57: ENTRADA | D57: 170.29 | E57: =SUMIF('Parametros Inventario'!$A:$A,B57,'Parametros Inventario'!$B:$B)+SUMIFS(D$2:D57,B$2:B57,B57,C$2:C57,"ENTRADA")-SUMIFS(D$2:D57,B$2:B57,B57,C$2:C57,"SALIDA") -> 1715.75
A58: 44050 | B58: Carnes blancas | C58: ENTRADA | D58: 127.43 | E58: =SUMIF('Parametros Inventario'!$A:$A,B58,'Parametros Inventario'!$B:$B)+SUMIFS(D$2:D58,B$2:B58,B58,C$2:C58,"ENTRADA")-SUMIFS(D$2:D58,B$2:B58,B58,C$2:C58,"SALIDA") -> 2218.54
A59: 44050 | B59: Lácteos | C59: ENTRADA | D59: 163.09 | E59: =SUMIF('Parametros Inventario'!$A:$A,B59,'Parametros Inventario'!$B:$B)+SUMIFS(D$2:D59,B$2:B59,B59,C$2:C59,"ENTRADA")-SUMIFS(D$2:D59,B$2:B59,B59,C$2:C59,"SALIDA") -> 1743.12
A60: 44050 | B60: Salsas | C60: ENTRADA | D60: 134.46 | E60: =SUMIF('Parametros Inventario'!$A:$A,B60,'Parametros Inventario'!$B:$B)+SUMIFS(D$2:D60,B$2:B60,B60,C$2:C60,"ENTRADA")-SUMIFS(D$2:D60,B$2:B60,B60,C$2:C60,"SALIDA") -> 2339.57
A61: 44050 | B61: Vegetales y hojas | C61: ENTRADA | D61: 144.33 | E61: =SUMIF('Parametros Inventario'!$A:$A,B61,'Parametros Inventario'!$B:$B)+SUMIFS(D$2:D61,B$2:B61,B61,C$2:C61,"ENTRADA")-SUMIFS(D$2:D61,B$2:B61,B61,C$2:C61,"SALIDA") -> 1807.76
A62: 44050 | B62: Aceite o grasas | C62: ENTRADA | D62: 258.61 | E62: =SUMIF('Parametros Inventario'!$A:$A,B62,'Parametros Inventario'!$B:$B)+SUMIFS(D$2:D62,B$2:B62,B62,C$2:C62,"ENTRADA")-SUMIFS(D$2:D62,B$2:B62,B62,C$2:C62,"SALIDA") -> 2274.64
A63: ='Volúmenes DIstribuidos '!B9 -> 44050 | B63: =IF(OR('Volúmenes DIstribuidos '!C9="Azúcar",'Volúmenes DIstribuidos '!C9="azúcar"),"Azúcar o dulce",IF('Volúmenes DIstribuidos '!C9="Aceite","Aceite o grasas",IF('Volúmenes DIstribuidos '!C9="Avena","Otros almidones",'Volúmenes DIstribuidos '!C9))) -> Menestras | C63: SALIDA | D63: ='Volúmenes DIstribuidos '!D9 -> 11.59 | E63: =SUMIF('Parametros Inventario'!$A:$A,B63,'Parametros Inventario'!$B:$B)+SUMIFS(D$2:D63,B$2:B63,B63,C$2:C63,"ENTRADA")-SUMIFS(D$2:D63,B$2:B63,B63,C$2:C63,"SALIDA") -> 1318.89
A64: ='Volúmenes DIstribuidos '!B9 -> 44050 | B64: =IF(OR('Volúmenes DIstribuidos '!C10="Azúcar",'Volúmenes DIstribuidos '!C10="azúcar"),"Azúcar o dulce",IF('Volúmenes DIstribuidos '!C10="Aceite","Aceite o grasas",IF('Volúmenes DIstribuidos '!C10="Avena","Otros almidones",'Volúmenes DIstribuidos '!C10))) -> Vegetales y hojas | C64: SALIDA | D64: ='Volúmenes DIstribuidos '!D10 -> 25.83 | E64: =SUMIF('Parametros Inventario'!$A:$A,B64,'Parametros Inventario'!$B:$B)+SUMIFS(D$2:D64,B$2:B64,B64,C$2:C64,"ENTRADA")-SUMIFS(D$2:D64,B$2:B64,B64,C$2:C64,"SALIDA") -> 1781.93
A65: ='Volúmenes DIstribuidos '!B9 -> 44050 | B65: =IF(OR('Volúmenes DIstribuidos '!C11="Azúcar",'Volúmenes DIstribuidos '!C11="azúcar"),"Azúcar o dulce",IF('Volúmenes DIstribuidos '!C11="Aceite","Aceite o grasas",IF('Volúmenes DIstribuidos '!C11="Avena","Otros almidones",'Volúmenes DIstribuidos '!C11))) -> Otros almidones | C65: SALIDA | D65: ='Volúmenes DIstribuidos '!D11 -> 8.371 | E65: =SUMIF('Parametros Inventario'!$A:$A,B65,'Parametros Inventario'!$B:$B)+SUMIFS(D$2:D65,B$2:B65,B65,C$2:C65,"ENTRADA")-SUMIFS(D$2:D65,B$2:B65,B65,C$2:C65,"SALIDA") -> 2019.409
A66: ='Volúmenes DIstribuidos '!B9 -> 44050 | B66: =IF(OR('Volúmenes DIstribuidos '!C12="Azúcar",'Volúmenes DIstribuidos '!C12="azúcar"),"Azúcar o dulce",IF('Volúmenes DIstribuidos '!C12="Aceite","Aceite o grasas",IF('Volúmenes DIstribuidos '!C12="Avena","Otros almidones",'Volúmenes DIstribuidos '!C12))) -> Carnes blancas | C66: SALIDA | D66: ='Volúmenes DIstribuidos '!D12 -> 20.34 | E66: =SUMIF('Parametros Inventario'!$A:$A,B66,'Parametros Inventario'!$B:$B)+SUMIFS(D$2:D66,B$2:B66,B66,C$2:C66,"ENTRADA")-SUMIFS(D$2:D66,B$2:B66,B66,C$2:C66,"SALIDA") -> 2198.2
A67: ='Volúmenes DIstribuidos '!B9 -> 44050 | B67: =IF(OR('Volúmenes DIstribuidos '!C13="Azúcar",'Volúmenes DIstribuidos '!C13="azúcar"),"Azúcar o dulce",IF('Volúmenes DIstribuidos '!C13="Aceite","Aceite o grasas",IF('Volúmenes DIstribuidos '!C13="Avena","Otros almidones",'Volúmenes DIstribuidos '!C13))) -> Azúcar o dulce | C67: SALIDA | D67: ='Volúmenes DIstribuidos '!D13 -> 22.34 | E67: =SUMIF('Parametros Inventario'!$A:$A,B67,'Parametros Inventario'!$B:$B)+SUMIFS(D$2:D67,B$2:B67,B67,C$2:C67,"ENTRADA")-SUMIFS(D$2:D67,B$2:B67,B67,C$2:C67,"SALIDA") -> 2633.41
A68: ='Volúmenes DIstribuidos '!B9 -> 44050 | B68: =IF(OR('Volúmenes DIstribuidos '!C14="Azúcar",'Volúmenes DIstribuidos '!C14="azúcar"),"Azúcar o dulce",IF('Volúmenes DIstribuidos '!C14="Aceite","Aceite o grasas",IF('Volúmenes DIstribuidos '!C14="Avena","Otros almidones",'Volúmenes DIstribuidos '!C14))) -> Fideo | C68: SALIDA | D68: ='Volúmenes DIstribuidos '!D14 -> 14.88 | E68: =SUMIF('Parametros Inventario'!$A:$A,B68,'Parametros Inventario'!$B:$B)+SUMIFS(D$2:D68,B$2:B68,B68,C$2:C68,"ENTRADA")-SUMIFS(D$2:D68,B$2:B68,B68,C$2:C68,"SALIDA") -> 2046.66
A69: ='Volúmenes DIstribuidos '!B15 -> 44054 | B69: =IF(OR('Volúmenes DIstribuidos '!C15="Azúcar",'Volúmenes DIstribuidos '!C15="azúcar"),"Azúcar o dulce",IF('Volúmenes DIstribuidos '!C15="Aceite","Aceite o grasas",IF('Volúmenes DIstribuidos '!C15="Avena","Otros almidones",'Volúmenes DIstribuidos '!C15))) -> Lácteos | C69: SALIDA | D69: ='Volúmenes DIstribuidos '!D15 -> 4.23 | E69: =SUMIF('Parametros Inventario'!$A:$A,B69,'Parametros Inventario'!$B:$B)+SUMIFS(D$2:D69,B$2:B69,B69,C$2:C69,"ENTRADA")-SUMIFS(D$2:D69,B$2:B69,B69,C$2:C69,"SALIDA") -> 1738.89
A70: ='Volúmenes DIstribuidos '!B15 -> 44054 | B70: =IF(OR('Volúmenes DIstribuidos '!C16="Azúcar",'Volúmenes DIstribuidos '!C16="azúcar"),"Azúcar o dulce",IF('Volúmenes DIstribuidos '!C16="Aceite","Aceite o grasas",IF('Volúmenes DIstribuidos '!C16="Avena","Otros almidones",'Volúmenes DIstribuidos '!C16))) -> Vegetales y hojas | C70: SALIDA | D70: ='Volúmenes DIstribuidos '!D16 -> 5.306 | E70: =SUMIF('Parametros Inventario'!$A:$A,B70,'Parametros Inventario'!$B:$B)+SUMIFS(D$2:D70,B$2:B70,B70,C$2:C70,"ENTRADA")-SUMIFS(D$2:D70,B$2:B70,B70,C$2:C70,"SALIDA") -> 1776.624
A71: ='Volúmenes DIstribuidos '!B15 -> 44054 | B71: =IF(OR('Volúmenes DIstribuidos '!C17="Azúcar",'Volúmenes DIstribuidos '!C17="azúcar"),"Azúcar o dulce",IF('Volúmenes DIstribuidos '!C17="Aceite","Aceite o grasas",IF('Volúmenes DIstribuidos '!C17="Avena","Otros almidones",'Volúmenes DIstribuidos '!C17))) -> Carnes blancas | C71: SALIDA | D71: ='Volúmenes DIstribuidos '!D17 -> 7.09 | E71: =SUMIF('Parametros Inventario'!$A:$A,B71,'Parametros Inventario'!$B:$B)+SUMIFS(D$2:D71,B$2:B71,B71,C$2:C71,"ENTRADA")-SUMIFS(D$2:D71,B$2:B71,B71,C$2:C71,"SALIDA") -> 2191.11
...

Sheet Parametros Inventario
A1: Categoría | B1: Stock inicial (kg)
A2: Azúcar o dulce | B2: 1957
A3: Otros almidones | B3: 1371
A4: Fideo | B4: 1343
A5: Panadería | B5: 667
A6: Menestras | B6: 688
A7: Carnes rojas | B7: 627
A8: Carnes blancas | B8: 1370
A9: Lácteos | B9: 766
A10: Salsas | B10: 1475
A11: Vegetales y hojas | B11: 939
A12: Aceite o grasas | B12: 1413
